Workbook

Sheet Итог
A1: Сверка таблиц поступлений (01.07–30.09.2026)
A2: A = файл 44970f48 (журнал поступлений, 13 колонок); B = файл 512c9963 (журнал с колонкой «Счет-фактура», 16 колонок). Сопоставление по полю «Номер».
A4: Строк в A | B4: =COUNTA('Полная сверка'!F2:F119) -> 118
A5: Строк в B | B5: =COUNTA('Полная сверка'!G2:G119) -> 114
A6: Сумма A, ₽ | B6: ='Полная сверка'!F120 -> 54006071
A7: Сумма B, ₽ | B7: ='Полная сверка'!G120 -> 51709045
A8: Разница A − B, ₽ | B8: =B6-B7 -> 2297026.4
A10: Документов нет в B | B10: =COUNTIF('Полная сверка'!O2:O119,"*Нет в B*") -> 4
A11: на сумму, ₽ | B11: =SUMIF('Полная сверка'!O2:O119,"*Нет в B*",'Полная сверка'!F2:F119) -> 2158737.5
A12: Документов с разной суммой | B12: =COUNTIF('Полная сверка'!O2:O119,"*сумма*") -> 5
A13: разница сумм, ₽ | B13: =SUMIF('Полная сверка'!O2:O119,"*сумма*",'Полная сверка'!H2:H119) -> 138288.86
A14: Проверка: объяснённая разница − общая разница (должно быть 0) | B14: =B11+B13-B8 -> 0
A16: Документов с разной датой | B16: =COUNTIF('Полная сверка'!O2:O119,"*дата*") -> 2
A17: Документов с разным складом | B17: =COUNTIF('Полная сверка'!O2:O119,"*склад*") -> 2
A18: Документов с разным комментарием | B18: =COUNTIF('Полная сверка'!O2:O119,"*комментарий*") -> 3
A19: Полностью совпадают | B19: =COUNTIF('Полная сверка'!O2:O119,"Совпадает") -> 104
A21: Примечания:
A22: • Суммы в B по 5 документам ровно в 1,22 раза меньше, чем в A — вероятно, в B указаны без НДС 22%.
A23: • 00НФ-000211 и 00НФ-000260 отсутствуют в B, в A помечены как «дубль».
A24: • 00НФ-000212 и 00НФ-000282 в A помечены «дубль», но в B присутствуют — проверить.
A25: • В B: у 00НФ-000196 «Счет-фактура» = «Отсутствует», у 00НФ-000225 — пусто.
A26: • Цвета: красный — расхождение по сумме / отсутствие документа; жёлтый — прочие расхождения.

Sheet Полная сверка
A1: Номер | B1: Дата (A) | C1: Дата (B) | D1: Контрагент (A) | E1: Контрагент (B) | F1: Сумма (A) | G1: Сумма (B) | H1: Разница A−B | I1: № вх. (A) | J1: № вх. (B) | K1: Склад (A) | L1: Склад (B) | M1: Комментарий (A) | N1: Комментарий (B) | O1: Статус
A2: 00НФ-000311 | B2: 01.07.2026 | C2: 01.07.2026 | D2: ЯКОВ ООО | E2: ЯКОВ ООО | F2: 7658 | G2: 7658 | H2: =N(F2)-N(G2) -> 0 | I2: 247 | J2: 247 | K2: Основной склад Зеллеон | O2: Совпадает
A3: 00НФ-000316 | B3: 01.07.2026 | C3: 01.07.2026 | D3: ЯКОВ ООО | E3: ЯКОВ ООО | F3: 7527.1 | G3: 7527.1 | H3: =N(F3)-N(G3) -> 0 | I3: 390 | J3: 390 | K3: Основной склад Зеллеон | O3: Совпадает
A4: 00НФ-000317 | B4: 01.07.2026 | C4: 01.07.2026 | D4: ЯКОВ ООО | E4: ЯКОВ ООО | F4: 6139.49 | G4: 6139.49 | H4: =N(F4)-N(G4) -> 0 | I4: 308 | J4: 308 | K4: Основной склад Зеллеон | O4: Совпадает
A5: 00НФ-000190 | B5: 02.07.2026 | C5: 02.07.2026 | D5: БРЕНД ТРЕЙД ООО | E5: БРЕНД ТРЕЙД ООО | F5: 1588100 | G5: 1588100 | H5: =N(F5)-N(G5) -> 0 | I5: 256 | J5: 256 | K5: Склад Z ОС | L5: Основной склад Зеллеон | M5: комплектуха ЧЛ | N5: комплектуха ЧЛ | O5: Расхождение: склад
A6: 00НФ-000191 | B6: 03.07.2026 | C6: 03.07.2026 | D6: Деловые Линии ООО | E6: Деловые Линии ООО | F6: 2234 | G6: 2234 | H6: =N(F6)-N(G6) -> 0 | I6: 1369361/0001 | J6: 1369361/0001 | K6: Основной склад Зеллеон | O6: Совпадает
A7: 00НФ-000193 | B7: 07.07.2026 | C7: 07.07.2026 | D7: БЕРКС ООО | E7: БЕРКС ООО | F7: 24890 | G7: 24890 | H7: =N(F7)-N(G7) -> 0 | I7: 2607070615 | J7: 2607070615 | K7: Основной склад Зеллеон | L7: Основной склад Зеллеон | O7: Совпадает
A8: 00НФ-000216 | B8: 08.07.2026 | C8: 08.07.2026 | D8: АКСОФТ АО | E8: АКСОФТ АО | F8: 836.01 | G8: 836.01 | H8: =N(F8)-N(G8) -> 0 | I8: Ax000040535 | J8: Ax000040535 | K8: Основной склад Зеллеон | L8: Основной склад Зеллеон | O8: Совпадает
A9: 00НФ-000208 | B9: 09.07.2026 | C9: 09.07.2026 | D9: ЭЛЕВЕЛ ИНЖЕНЕР АО | E9: ЭЛЕВЕЛ ИНЖЕНЕР АО | F9: 85498.9 | G9: 85498.9 | H9: =N(F9)-N(G9) -> 0 | I9: ЭИ00-0054586 | J9: ЭИ00-0054586 | K9: Основной склад Зеллеон | L9: Основной склад Зеллеон | O9: Совпадает
A10: 00НФ-000209 | B10: 09.07.2026 | C10: 09.07.2026 | D10: Деловые Линии ООО | E10: Деловые Линии ООО | F10: 8795 | G10: 8795 | H10: =N(F10)-N(G10) -> 0 | I10: 1349568/0001 | J10: 1349568/0001 | K10: Основной склад Зеллеон | O10: Совпадает
A11: 00НФ-000196 | B11: 09.07.2026 | C11: 09.07.2026 | D11: Киселева Валентина Матвеевна | E11: Киселева Валентина Матвеевна | F11: 27252 | G11: 27252 | H11: =N(F11)-N(G11) -> 0 | I11: 285 | J11: 285 | K11: Основной склад Зеллеон | L11: Основной склад Зеллеон | O11: Совпадает
A12: 00НФ-000199 | B12: 09.07.2026 | C12: 09.07.2026 | D12: ИП Кожевников Сергей Юрьевич | E12: ИП Кожевников Сергей Юрьевич | F12: 22900 | G12: 22900 | H12: =N(F12)-N(G12) -> 0 | I12: 1242 | J12: 1242 | K12: Основной склад Зеллеон | L12: Основной склад Зеллеон | O12: Совпадает
A13: 00НФ-000203 | B13: 10.07.2026 | C13: 10.07.2026 | D13: ГЕТСИ ЛОГИСТИК ООО (МСК) | E13: ГЕТСИ ЛОГИСТИК ООО (МСК) | F13: 15110.07 | G13: 15110.07 | H13: =N(F13)-N(G13) -> 0 | I13: ГЛ26004447 | J13: ГЛ26004447 | K13: Основной склад Зеллеон | L13: Основной склад Зеллеон | O13: Совпадает
A14: 00НФ-000207 | B14: 10.07.2026 | C14: 10.07.2026 | D14: Деловые Линии ООО | E14: Деловые Линии ООО | F14: 104329 | G14: 104329 | H14: =N(F14)-N(G14) -> 0 | I14: 1376705/0001 | J14: 1376705/0001 | K14: Основной склад Зеллеон | O14: Совпадает
A15: 00НФ-000200 | B15: 10.07.2026 | C15: 10.07.2026 | D15: РЭБИС ООО | E15: РЭБИС ООО | F15: 39500 | G15: 39500 | H15: =N(F15)-N(G15) -> 0 | I15: 18 | J15: 18 | K15: Основной склад Зеллеон | O15: Совпадает
A16: 00НФ-000205 | B16: 11.07.2026 | C16: 11.07.2026 | D16: БЕРКС ООО | E16: БЕРКС ООО | F16: 2092208.8 | G16: 2092208.8 | H16: =N(F16)-N(G16) -> 0 | I16: 2607110080 | J16: 2607110080 | K16: Основной склад Зеллеон | L16: Основной склад Зеллеон | O16: Совпадает
A17: 00НФ-000206 | B17: 11.07.2026 | C17: 11.07.2026 | D17: Деловые Линии ООО | E17: Деловые Линии ООО | F17: 6218 | G17: 6218 | H17: =N(F17)-N(G17) -> 0 | I17: 1369360/0001 | J17: 1369360/0001 | K17: Основной склад Зеллеон | O17: Совпадает
A18: 00НФ-000218 | B18: 13.07.2026 | C18: 13.07.2026 | D18: НОВЫЙ АЙ ТИ ПРОЕКТ ООО | E18: НОВЫЙ АЙ ТИ ПРОЕКТ ООО | F18: 18697.76 | G18: 18697.76 | H18: =N(F18)-N(G18) -> 0 | I18: 51295Л26 | J18: 51295Л26 | K18: Основной склад Зеллеон | L18: Основной склад Зеллеон | O18: Совпадает
A19: 00НФ-000204 | B19: 13.07.2026 | C19: 13.07.2026 | D19: ДНС РИТЕЙЛ ООО (ЛО) | E19: ДНС РИТЕЙЛ ООО (ЛО) | F19: 478794 | G19: 478794 | H19: =N(F19)-N(G19) -> 0 | I19: Г-00368210/11094 | J19: Г-00368210/11094 | K19: Основной склад Зеллеон | L19: Основной склад Зеллеон | O19: Совпадает
A20: 00НФ-000215 | B20: 14.07.2026 | C20: 14.07.2026 | D20: ЛАНДИС ООО | E20: ЛАНДИС ООО | F20: 110376.05 | G20: 110376.05 | H20: =N(F20)-N(G20) -> 0 | I20: 14-07-0153 | J20: 14-07-0153 | K20: Основной склад Зеллеон | L20: Основной склад Зеллеон | O20: Совпадает
A21: 00НФ-000226 | B21: 15.07.2026 | C21: 15.07.2026 | D21: ГЕТСИ ЛОГИСТИК ООО (МСК) | E21: ГЕТСИ ЛОГИСТИК ООО (МСК) | F21: 10053.29 | G21: 10053.29 | H21: =N(F21)-N(G21) -> 0 | I21: ГЛ26004549 | J21: ГЛ26004549 | K21: Основной склад Зеллеон | L21: Основной склад Зеллеон | O21: Совпадает
A22: 00НФ-000232 | B22: 15.07.2026 | C22: 15.07.2026 | D22: Обособленное подразделение "ДНС Ритейл ООО | E22: Обособленное подразделение "ДНС Ритейл ООО | F22: 66897 | G22: 66897 | H22: =N(F22)-N(G22) -> 0 | I22: Г-00412103/11134 | J22: Г-00412103/11134 | K22: Основной склад Зеллеон | L22: Основной склад Зеллеон | O22: Совпадает
A23: 00НФ-000233 | B23: 15.07.2026 | C23: 15.07.2026 | D23: Обособленное подразделение "ДНС Ритейл ООО | E23: Обособленное подразделение "ДНС Ритейл ООО | F23: 478794 | G23: 478794 | H23: =N(F23)-N(G23) -> 0 | I23: Г-00401504/11134 | J23: Г-00401504/11134 | K23: Основной склад Зеллеон | L23: Основной склад Зеллеон | O23: Совпадает
A24: 00НФ-000234 | B24: 15.07.2026 | C24: 15.07.2026 | D24: Обособленное подразделение "ДНС Ритейл ООО | E24: Обособленное подразделение "ДНС Ритейл ООО | F24: 159598 | G24: 159598 | H24: =N(F24)-N(G24) -> 0 | I24: Г-00401807/11134 | J24: Г-00401807/11134 | K24: Основной склад Зеллеон | L24: Основной склад Зеллеон | O24: Совпадает
A25: 00НФ-000235 | B25: 15.07.2026 | C25: 15.07.2026 | D25: Обособленное подразделение "ДНС Ритейл ООО | E25: Обособленное подразделение "ДНС Ритейл ООО | F25: 70499 | G25: 70499 | H25: =N(F25)-N(G25) -> 0 | I25: Г-00368225/11134 | J25: Г-00368225/11134 | K25: Основной склад Зеллеон | L25: Основной склад Зеллеон | O25: Совпадает
A26: 00НФ-000211 | B26: 15.07.2026 | D26: КАРИН ООО | F26: 17995.23 | H26: =N(F26)-N(G26) -> 17995.23 | I26: КР04–30/81 | K26: Основной склад Зеллеон | M26: дублдь | O26: Расхождение: Нет в B
A27: 00НФ-000212 | B27: 15.07.2026 | C27: 15.07.2026 | D27: Обособленное подразделение "ДНС Ритейл ООО | E27: Обособленное подразделение "ДНС Ритейл ООО | F27: 159598 | G27: 159598 | H27: =N(F27)-N(G27) -> 0 | I27: проверит | J27: проверит | K27: Основной склад Зеллеон | L27: Основной склад Зеллеон | M27: дубль | O27: Расхождение: комментарий
A28: 00НФ-000213 | B28: 15.07.2026 | C28: 15.07.2026 | D28: ГРИНПЛЕЙС ООО | E28: ГРИНПЛЕЙС ООО | F28: 70914.85 | G28: 70914.85 | H28: =N(F28)-N(G28) -> 0 | I28: 2607150032 | J28: 2607150032 | K28: Основной склад Зеллеон | L28: Основной склад Зеллеон | O28: Совпадает
A29: 00НФ-000214 | B29: 15.07.2026 | C29: 15.07.2026 | D29: БЕРКС ООО | E29: БЕРКС ООО | F29: 152682.69 | G29: 152682.69 | H29: =N(F29)-N(G29) -> 0 | I29: 2607150549 | J29: 2607150549 | K29: Основной склад Зеллеон | L29: Основной склад Зеллеон | O29: Совпадает
A30: 00НФ-000217 | B30: 15.07.2026 | C30: 15.07.2026 | D30: БЕРКС ООО | E30: БЕРКС ООО | F30: 93451 | G30: 93451 | H30: =N(F30)-N(G30) -> 0 | I30: 2607090427 | J30: 2607090427 | K30: Основной склад Зеллеон | L30: Основной склад Зеллеон | O30: Совпадает
A31: 00НФ-000219 | B31: 15.07.2026 | C31: 15.07.2026 | D31: ГЕТСИ ЛОГИСТИК ООО (МСК) | E31: ГЕТСИ ЛОГИСТИК ООО (МСК) | F31: 48424.64 | G31: 48424.64 | H31: =N(F31)-N(G31) -> 0 | I31: ГЛ26004516 | J31: ГЛ26004516 | K31: Основной склад Зеллеон | L31: Основной склад Зеллеон | O31: Совпадает
A32: 00НФ-000220 | B32: 15.07.2026 | C32: 15.07.2026 | D32: БЕРКС ООО | E32: БЕРКС ООО | F32: 131344.47 | G32: 131344.47 | H32: =N(F32)-N(G32) -> 0 | I32: 2607150550 | J32: 2607150550 | K32: Основной склад Зеллеон | L32: Основной склад Зеллеон | O32: Совпадает
A33: 00НФ-000256 | B33: 15.07.2026 | C33: 15.07.2026 | D33: ПРОФ РУ КОМ ООО | E33: ПРОФ РУ КОМ ООО | F33: 19002.08 | G33: 19002.08 | H33: =N(F33)-N(G33) -> 0 | I33: 475 | J33: 475 | K33: Основной склад Зеллеон | L33: Основной склад Зеллеон | O33: Совпадает
A34: 00НФ-000225 | B34: 17.07.2026 | C34: 17.07.2026 | D34: БЕРКС ООО | E34: БЕРКС ООО | F34: 32944.47 | G34: 32944.47 | H34: =N(F34)-N(G34) -> 0 | I34: 2607170599 | J34: 2607170599 | K34: Основной склад Зеллеон | L34: Основной склад Зеллеон | O34: Совпадает
A35: 00НФ-000230 | B35: 20.07.2026 | C35: 20.07.2026 | D35: Деловые Линии ООО | E35: Деловые Линии ООО | F35: 3992 | G35: 3992 | H35: =N(F35)-N(G35) -> 0 | I35: 1404141/0001 | J35: 1404141/0001 | K35: Основной склад Зеллеон | O35: Совпадает
A36: 00НФ-000229 | B36: 22.07.2026 | C36: 22.07.2026 | D36: Обособленное подразделение "ДНС Ритейл ООО (Пятигорск) | E36: Обособленное подразделение "ДНС Ритейл ООО (Пятигорск) | F36: 309364 | G36: 309364 | H36: =N(F36)-N(G36) -> 0 | I36: Е-00276002/5209 | J36: Е-00276002/5209 | K36: Основной склад Зеллеон | L36: Основной склад Зеллеон | O36: Совпадает
A37: 00НФ-000224 | B37: 23.07.2026 | C37: 23.07.2026 | D37: ЛАНДИС ООО | E37: ЛАНДИС ООО | F37: 68662.23 | G37: 68662.23 | H37: =N(F37)-N(G37) -> 0 | I37: 23-07-0252 | J37: 23-07-0252 | K37: Основной склад Зеллеон | L37: Основной склад Зеллеон | O37: Совпадает
A38: 00НФ-000227 | B38: 23.07.2026 | C38: 23.07.2026 | D38: ЛАНДИС ООО | E38: ЛАНДИС ООО | F38: 441560.23 | G38: 441560.23 | H38: =N(F38)-N(G38) -> 0 | I38: 23-07-0251 | J38: 23-07-0251 | K38: Основной склад Зеллеон | L38: Основной склад Зеллеон | O38: Совпадает
A39: 00НФ-000228 | B39: 23.07.2026 | C39: 23.07.2026 | D39: ЛАНДИС ООО | E39: ЛАНДИС ООО | F39: 230376.9 | G39: 230376.9 | H39: =N(F39)-N(G39) -> 0 | I39: 23-07-0253 | J39: 23-07-0253 | K39: Основной склад Зеллеон | L39: Основной склад Зеллеон | O39: Совпадает
A40: 00НФ-000231 | B40: 23.07.2026 | C40: 23.07.2026 | D40: ПЭК ООО | E40: ПЭК ООО | F40: 1687.1 | G40: 1687.1 | H40: =N(F40)-N(G40) -> 0 | I40: СПП0720000065/78 | J40: СПП0720000065/78 | K40: Основной склад Зеллеон | O40: Совпадает
...

Sheet Расхождения
A1: № | B1: Тип расхождения | C1: Номер | D1: Контрагент | E1: Значение в A | F1: Значение в B | G1: Разница A−B, ₽ | H1: Пояснение
A2: 1 | B2: Нет в таблице B | C2: 00НФ-000211 | D2: КАРИН ООО | E2: 17995.23 | G2: =E2 -> 17995.23 | H2: Комментарий в A: дублдь; склад: Основной склад Зеллеон
A3: 2 | B3: Нет в таблице B | C3: 00НФ-000260 | D3: БЕРКС ООО | E3: 2092208.8 | G3: =E3 -> 2092208.8 | H3: Комментарий в A: дубль; склад: Основной склад Зеллеон
A4: 3 | B4: Нет в таблице B | C4: 00НФ-000318 | D4: ЛИКАРД ООО | E4: 47349.79 | G4: =E4 -> 47349.79 | H4: Комментарий в A: —; склад: Основной склад ИП
A5: 4 | B5: Нет в таблице B | C5: 00НФ-000319 | D5: ЛИКАРД ООО | E5: 1183.74 | G5: =E5 -> 1183.74 | H5: Комментарий в A: —; склад: Основной склад ИП
A6: 5 | B6: Сумма | C6: 00НФ-000276 | D6: СЕЛЕКТИС ООО | E6: 197700 | F6: 162049.18 | G6: =E6-F6 -> 35650.82 | H6: A/B = 1.22 — в B сумма без НДС 22%
A7: 6 | B7: Сумма | C7: 00НФ-000279 | D7: Обособленное подразделение "ДНС Ритейл ООО | E7: 136794 | F7: 112126.23 | G7: =E7-F7 -> 24667.77 | H7: A/B = 1.22 — в B сумма без НДС 22%
A8: 7 | B8: Сумма | C8: 00НФ-000280 | D8: ДНС РИТЕЙЛ ООО | E8: 152985 | F8: 125397.54 | G8: =E8-F8 -> 27587.46 | H8: A/B = 1.22 — в B сумма без НДС 22%
A9: 8 | B9: Сумма | C9: 00НФ-000281 | D9: ДНС РИТЕЙЛ ООО | E9: 214179 | F9: 175556.56 | G9: =E9-F9 -> 38622.44 | H9: A/B = 1.22 — в B сумма без НДС 22%
A10: 9 | B10: Сумма | C10: 00НФ-000308 | D10: ГЕТСИ ЛОГИСТИК ООО (ЛО) | E10: 65216.58 | F10: 53456.21 | G10: =E10-F10 -> 11760.37 | H10: A/B = 1.22 — в B сумма без НДС 22%
A11: 10 | B11: Дата | C11: 00НФ-000246 | D11: БЕРКС ООО | E11: 03.08.2026 | F11: 30.07.2026 | H11: коррекция до 1 102 888,39-дата изменена на 30.07,для списания
A12: 11 | B12: Дата | C12: 00НФ-000258 | D12: БЕРКС ООО | E12: 20.08.2026 | F12: 18.08.2026
A13: 12 | B13: Склад | C13: 00НФ-000190 | D13: БРЕНД ТРЕЙД ООО | E13: Склад Z ОС | F13: Основной склад Зеллеон
A14: 13 | B14: Склад | C14: 00НФ-000281 | D14: ДНС РИТЕЙЛ ООО | E14: Основной склад ИП | F14: Основной склад Зеллеон
A15: 14 | B15: Комментарий | C15: 00НФ-000212 | D15: Обособленное подразделение "ДНС Ритейл ООО | E15: дубль | F15: (пусто) | H15: В A помечен как дубль, в B присутствует без пометки — проверить
A16: 15 | B16: Комментарий | C16: 00НФ-000282 | D16: ЭЛТЕКС СПБ ООО | E16: дубль | F16: (пусто) | H16: В A помечен как дубль, в B присутствует без пометки — проверить
